<mujoco model="franka_research_3">
  <compiler angle="radian" meshdir="assets" />

  <option integrator="implicitfast" />

  <default>
    <default class="franka_research_3">
      <!-- Overwritten in joints 5, 6, and 7. -->
      <joint damping="0.21" armature="0.195" frictionloss="1.137" />
      <position inheritrange="1" />
      <default class="visual">
        <geom type="mesh" group="2" contype="0" conaffinity="0" />
      </default>
      <default class="collision">
        <geom type="mesh" group="3" mass="0" density="0" />
      </default>
    </default>
  </default>

  <asset>
    <mesh name="link0" file="collision/link0.stl" />
    <mesh name="link1" file="collision/link1.stl" />
    <mesh name="link2" file="collision/link2.stl" />
    <mesh name="link3" file="collision/link3.stl" />
    <mesh name="link4" file="collision/link4.stl" />
    <mesh name="link5" file="collision/link5.stl" />
    <mesh name="link6" file="collision/link6.stl" />
    <mesh name="link7" file="collision/link7.stl" />
    <mesh name="hand" file="collision/hand.stl" />
  </asset>

  <worldbody>
    <body name="base" childclass="franka_research_3">
      <body name="link0">
        <geom mesh="link0" class="collision" />
        <geom mesh="link0" class="visual" />
        <body name="link1" pos="0 0 0.333">
          <inertial
                        pos="4.128e-07 -0.0181251 -0.0386036"
                        quat="0.998098 -0.0605364 0.00380499 0.0110109"
                        mass="2.92747"
                        diaginertia="0.0239286 0.0227246 0.00610634"
                    />
          <joint name="joint0" axis="0 0 1" range="-2.8973 2.8973" actuatorfrcrange="-87 87" />
          <geom mesh="link1" class="collision" />
          <geom mesh="link1" class="visual" />
          <body name="link2">
            <inertial
                            pos="0.00318289 -0.0743222 0.00881461"
                            quat="0.502599 0.584437 -0.465998 0.434366"
                            mass="2.93554"
                            diaginertia="0.0629567 0.0411924 0.0246371"
                        />
            <joint name="joint1" axis="0 1 0" range="-1.7628 1.7628" actuatorfrcrange="-87 87" />
            <geom mesh="link2" class="collision" />
            <geom mesh="link2" class="visual" />
            <body name="link3" pos="0 0 0.316">
              <inertial
                                pos="0.0407016 -0.00482006 -0.0289731"
                                quat="0.921025 -0.244161 0.155272 0.260745"
                                mass="2.2449"
                                diaginertia="0.0267409 0.0189869 0.0171587"
                            />
              <joint name="joint2" axis="0 0 1" range="-2.8973 2.8973" actuatorfrcrange="-87 87" />
              <geom mesh="link3" class="collision" />
              <geom mesh="link3" class="visual" />
              <body name="link4" pos="0.0825 0 0">
                <inertial
                                    pos="-0.0459101 0.0630493 -0.00851879"
                                    quat="0.438018 0.803311 0.00937812 0.403414"
                                    mass="2.6156"
                                    diaginertia="0.05139 0.0372717 0.0160047"
                                />
                <joint
                                    name="joint3"
                                    axis="0 -1 0"
                                    range="-3.0718 -0.0698"
                                    actuatorfrcrange="-87 87"
                                />
                <geom mesh="link4" class="collision" />
                <geom mesh="link4" class="visual" />
                <body name="link5" pos="-0.0825 0 0.384">
                    <inertial
                                        pos="-0.00160396 0.0292536 -0.0972966"
                                        quat="0.919031 0.125604 0.0751531 -0.366003"
                                        mass="2.32712"
                                        diaginertia="0.0579335 0.0449144 0.0130634"
                                    />
                  <joint
                                        name="joint4"
                                        axis="0 0 1"
                                        range="-2.8973 2.8973"
                                        actuatorfrcrange="-12 12"
                                        armature="0.074"
                                        frictionloss="0.763"
                                    />
                  <geom mesh="link5" class="collision" />
                  <geom mesh="link5" class="visual" />
                  <body name="link6">
                    <inertial
                                            pos="0.0597131 -0.0410295 -0.0101693"
                                            quat="0.621301 0.552665 0.510011 0.220081"
                                            mass="1.81704"
                                            diaginertia="0.0175039 0.0161123 0.00193529"
                                        />
                    <joint
                                            name="joint5"
                                            axis="0 -1 0"
                                            range="-0.0175 3.7525"
                                            actuatorfrcrange="-12 12"
                                            armature="0.074"
                                            frictionloss="0.44"
                                        />
                    <geom mesh="link6" class="collision" />
                    <geom mesh="link6" class="visual" />
                    <body name="link7" pos="0.088 0 0">
                      <inertial
                                                pos="0.00452258 0.00862619 -0.0161633"
                                                quat="0.727579 0.0978688 -0.24906 0.63168"
                                                mass="0.627143"
                                                diaginertia="0.000223836 0.000223642 5.64132e-07"
                                            />
                      <joint
                                                name="joint6"
                                                axis="0 0 1"
                                                range="-2.8973 2.8973"
                                                actuatorfrcrange="-12 12"
                                                armature="0.074"
                                                frictionloss="0.248"
                                            />
                      <geom mesh="link7" class="collision" />
                      <geom mesh="link7" class="visual" />
                      <body name="hand" pos="0 0 -0.107">
                        <inertial
                                                    mass="0.73"
                                                    pos="-0.01 0 0.03"
                                                    diaginertia="0.001 0.0025 0.0017"
                                                />
                        <geom mesh="hand" class="collision" />
                        <geom mesh="hand" class="visual" />
                      </body>
                    </body>
                  </body>
                </body>
              </body>
            </body>
          </body>
        </body>
      </body>
    </body>
  </worldbody>

  <actuator>
    <position class="franka_research_3" name="joint0" joint="joint0" kp="160" kv="50" />
    <position class="franka_research_3" name="joint1" joint="joint1" kp="160" kv="50" />
    <position class="franka_research_3" name="joint2" joint="joint2" kp="160" kv="50" />
    <position class="franka_research_3" name="joint3" joint="joint3" kp="160" kv="50" />
    <position class="franka_research_3" name="joint4" joint="joint4" kp="80" kv="50" />
    <position class="franka_research_3" name="joint5" joint="joint5" kp="80" kv="50" />
    <position class="franka_research_3" name="joint6" joint="joint6" kp="80" kv="50" />
  </actuator>

</mujoco>
